2025-09-13T03:22:51 {"cpu": 0.66748046875, "cpu_total": 8, "cpu_usage": 0.08343505859375, "memory": 7054.0, "memory_total": 15719.0, "memory_usage": 0.4487562822062472, "pipeline_run_id": 4, "pipeline_schedule_id": 1, "pipeline_uuid": "qb_invoices_backfill", "hostname": "3dcda474a3e7", "level": "INFO", "message": "Pipeline qb_invoices_backfill for run 4 in schedule 1 is alive.", "timestamp": 1757733771.975138, "uuid": "eefe1a14b9f248b9b1b7b9b634724283"}
2025-09-13T03:22:52 {"cpu": 0.66748046875, "cpu_total": 8, "cpu_usage": 0.08343505859375, "memory": 7073.0, "memory_total": 15719.0, "memory_usage": 0.44996501049685095, "pipeline_run_id": 4, "pipeline_schedule_id": 1, "pipeline_uuid": "qb_invoices_backfill", "hostname": "3dcda474a3e7", "level": "INFO", "message": "Pipeline qb_invoices_backfill for run 4 in schedule 1 is alive.", "timestamp": 1757733772.004325, "uuid": "2c7e487b41ec47e092854873c11dce77"}
2025-09-13T03:22:52 {"block_run_id": 7, "block_uuid": "extract_qb_invoices", "pipeline_run_id": 4, "pipeline_schedule_id": 1, "pipeline_uuid": "qb_invoices_backfill", "hostname": "3dcda474a3e7", "level": "INFO", "message": "Execute PipelineRun 4, BlockRun 7: pipeline qb_invoices_backfill block extract_qb_invoices", "timestamp": 1757733772.022462, "uuid": "5aca91e2cd244c1189c3616ddb7e244d"}
2025-09-13T03:22:54 {"block_run_id": 7, "block_uuid": "extract_qb_invoices", "pipeline_run_id": 4, "pipeline_schedule_id": 1, "pipeline_uuid": "qb_invoices_backfill", "hostname": "3dcda474a3e7", "level": "INFO", "message": "BlockRun 7 (block_uuid: extract_qb_invoices) completes.", "timestamp": 1757733774.205275, "uuid": "4357d655cd954951b88d4c609cd8b2a5"}
2025-09-13T03:23:01 {"cpu": 0.6708984375, "cpu_total": 8, "cpu_usage": 0.0838623046875, "memory": 7311.0, "memory_total": 15719.0, "memory_usage": 0.46510592276862395, "pipeline_run_id": 4, "pipeline_schedule_id": 1, "pipeline_uuid": "qb_invoices_backfill", "hostname": "3dcda474a3e7", "level": "INFO", "message": "Pipeline qb_invoices_backfill for run 4 in schedule 1 is alive.", "timestamp": 1757733781.038387, "uuid": "9d671f75e0f14360a02d2d91c73c4d7e"}
2025-09-13T03:23:01 {"block_run_id": 8, "block_uuid": "save_to_raw_invoices", "pipeline_run_id": 4, "pipeline_schedule_id": 1, "pipeline_uuid": "qb_invoices_backfill", "hostname": "3dcda474a3e7", "level": "INFO", "message": "Execute PipelineRun 4, BlockRun 8: pipeline qb_invoices_backfill block save_to_raw_invoices", "timestamp": 1757733781.090617, "uuid": "40cdeb05511242ed974d682ed0fe6eba"}
2025-09-13T03:23:01 {"block_run_id": 8, "block_uuid": "save_to_raw_invoices", "pipeline_run_id": 4, "pipeline_schedule_id": 1, "pipeline_uuid": "qb_invoices_backfill", "hostname": "3dcda474a3e7", "level": "EXCEPTION", "message": "BlockRun 8 (block_uuid: save_to_raw_invoices) failed.", "timestamp": 1757733781.873232, "uuid": "b5dd4bb8cb3443cb909464611051f26d", "error": "Traceback (most recent call last):\n  File \"/usr/local/lib/python3.10/site-packages/mage_ai/data_preparation/executors/block_executor.py\", line 647, in execute\n    result = __execute_with_retry()\n  File \"/usr/local/lib/python3.10/site-packages/mage_ai/shared/retry.py\", line 54, in retry_func\n    raise e\n  File \"/usr/local/lib/python3.10/site-packages/mage_ai/shared/retry.py\", line 38, in retry_func\n    return func(*args, **kwargs)\n  File \"/usr/local/lib/python3.10/site-packages/mage_ai/data_preparation/executors/block_executor.py\", line 621, in __execute_with_retry\n    return self._execute(\n  File \"/usr/local/lib/python3.10/site-packages/mage_ai/data_preparation/executors/block_executor.py\", line 1154, in _execute\n    result = self.block.execute_sync(\n  File \"/usr/local/lib/python3.10/site-packages/mage_ai/data_preparation/models/block/__init__.py\", line 1691, in execute_sync\n    return __execute()\n  File \"/usr/local/lib/python3.10/site-packages/mage_ai/data_preparation/models/block/__init__.py\", line 1668, in __execute\n    raise err\n  File \"/usr/local/lib/python3.10/site-packages/mage_ai/data_preparation/models/block/__init__.py\", line 1570, in __execute\n    output = self.execute_block(\n  File \"/usr/local/lib/python3.10/site-packages/mage_ai/data_preparation/models/block/__init__.py\", line 1910, in execute_block\n    outputs = self._execute_block(\n  File \"/usr/local/lib/python3.10/site-packages/mage_ai/data_preparation/models/block/__init__.py\", line 2073, in _execute_block\n    outputs = self.execute_block_function(\n  File \"/usr/local/lib/python3.10/site-packages/mage_ai/data_preparation/models/block/__init__.py\", line 2169, in execute_block_function\n    output = block_function_updated(*input_vars, **global_vars)\n  File \"<string>\", line 61, in save_to_raw_customers\n  File \"/usr/local/lib/python3.10/site-packages/mage_ai/io/sql.py\", line 380, in export\n    __process()\n  File \"/usr/local/lib/python3.10/site-packages/mage_ai/io/sql.py\", line 360, in __process\n    self.upload_dataframe(\n  File \"/usr/local/lib/python3.10/site-packages/mage_ai/io/postgres.py\", line 415, in upload_dataframe\n    cursor.copy_expert(f\"\"\"\npsycopg2.errors.UniqueViolation: duplicate key value violates unique constraint \"qb_customers_pkey\"\nDETAIL:  Key (id)=(1) already exists.\nCONTEXT:  COPY qb_customers, line 1\n\n", "error_stack": ["  File \"/usr/local/bin/mage\", line 8, in <module>\n    sys.exit(app())\n", "  File \"/usr/local/lib/python3.10/site-packages/typer/main.py\", line 311, in __call__\n    return get_command(self)(*args, **kwargs)\n", "  File \"/usr/local/lib/python3.10/site-packages/click/core.py\", line 1442, in __call__\n    return self.main(*args, **kwargs)\n", "  File \"/usr/local/lib/python3.10/site-packages/typer/core.py\", line 778, in main\n    return _main(\n", "  File \"/usr/local/lib/python3.10/site-packages/typer/core.py\", line 216, in _main\n    rv = self.invoke(ctx)\n", "  File \"/usr/local/lib/python3.10/site-packages/click/core.py\", line 1830, in invoke\n    return _process_result(sub_ctx.command.invoke(sub_ctx))\n", "  File \"/usr/local/lib/python3.10/site-packages/click/core.py\", line 1226, in invoke\n    return ctx.invoke(self.callback, **ctx.params)\n", "  File \"/usr/local/lib/python3.10/site-packages/click/core.py\", line 794, in invoke\n    return callback(*args, **kwargs)\n", "  File \"/usr/local/lib/python3.10/site-packages/typer/main.py\", line 683, in wrapper\n    return callback(**use_params)  # type: ignore\n", "  File \"/usr/local/lib/python3.10/site-packages/mage_ai/cli/main.py\", line 147, in start\n    start_server(\n", "  File \"/usr/local/lib/python3.10/site-packages/mage_ai/server/server.py\", line 809, in start_server\n    scheduler_manager.start_scheduler()\n", "  File \"/usr/local/lib/python3.10/site-packages/mage_ai/server/scheduler_manager.py\", line 108, in start_scheduler\n    proc.start()\n", "  File \"/usr/local/lib/python3.10/multiprocessing/process.py\", line 121, in start\n    self._popen = self._Popen(self)\n", "  File \"/usr/local/lib/python3.10/multiprocessing/context.py\", line 224, in _Popen\n    return _default_context.get_context().Process._Popen(process_obj)\n", "  File \"/usr/local/lib/python3.10/multiprocessing/context.py\", line 281, in _Popen\n    return Popen(process_obj)\n", "  File \"/usr/local/lib/python3.10/multiprocessing/popen_fork.py\", line 19, in __init__\n    self._launch(process_obj)\n", "  File \"/usr/local/lib/python3.10/multiprocessing/popen_fork.py\", line 71, in _launch\n    code = process_obj._bootstrap(parent_sentinel=child_r)\n", "  File \"/usr/local/lib/python3.10/multiprocessing/process.py\", line 314, in _bootstrap\n    self.run()\n", "  File \"/usr/local/lib/python3.10/multiprocessing/process.py\", line 108, in run\n    self._target(*self._args, **self._kwargs)\n", "  File \"/usr/local/lib/python3.10/site-packages/mage_ai/orchestration/db/process.py\", line 15, in start_session_and_run\n    results = target(*args)\n", "  File \"/usr/local/lib/python3.10/site-packages/mage_ai/server/scheduler_manager.py\", line 60, in run_scheduler\n    LoopTimeTrigger().start()\n", "  File \"/usr/local/lib/python3.10/site-packages/mage_ai/orchestration/triggers/loop_time_trigger.py\", line 14, in start\n    self.run()\n", "  File \"/usr/local/lib/python3.10/site-packages/mage_ai/orchestration/triggers/time_trigger.py\", line 11, in run\n    schedule_all()\n", "  File \"/usr/local/lib/python3.10/site-packages/mage_ai/orchestration/pipeline_scheduler_original.py\", line 1819, in schedule_all\n    PipelineScheduler(r).schedule()\n", "  File \"/usr/local/lib/python3.10/site-packages/mage_ai/orchestration/db/__init__.py\", line 159, in func_with_rollback\n    return func(*args, **kwargs)\n", "  File \"/usr/local/lib/python3.10/site-packages/mage_ai/orchestration/pipeline_scheduler_original.py\", line 334, in schedule\n    self.__schedule_blocks(block_runs)\n", "  File \"/usr/local/lib/python3.10/site-packages/mage_ai/orchestration/pipeline_scheduler_original.py\", line 641, in __schedule_blocks\n    job_manager.add_job(\n", "  File \"/usr/local/lib/python3.10/site-packages/mage_ai/orchestration/job_manager.py\", line 21, in add_job\n    self.queue.enqueue(job_id, target, *args, **kwargs)\n", "  File \"/usr/local/lib/python3.10/site-packages/mage_ai/orchestration/queue/process_queue.py\", line 122, in enqueue\n    self.start_worker_pool()\n", "  File \"/usr/local/lib/python3.10/site-packages/mage_ai/orchestration/queue/process_queue.py\", line 199, in start_worker_pool\n    self.worker_pool_proc.start()\n", "  File \"/usr/local/lib/python3.10/multiprocessing/process.py\", line 121, in start\n    self._popen = self._Popen(self)\n", "  File \"/usr/local/lib/python3.10/multiprocessing/context.py\", line 224, in _Popen\n    return _default_context.get_context().Process._Popen(process_obj)\n", "  File \"/usr/local/lib/python3.10/multiprocessing/context.py\", line 281, in _Popen\n    return Popen(process_obj)\n", "  File \"/usr/local/lib/python3.10/multiprocessing/popen_fork.py\", line 19, in __init__\n    self._launch(process_obj)\n", "  File \"/usr/local/lib/python3.10/multiprocessing/popen_fork.py\", line 71, in _launch\n    code = process_obj._bootstrap(parent_sentinel=child_r)\n", "  File \"/usr/local/lib/python3.10/multiprocessing/process.py\", line 314, in _bootstrap\n    self.run()\n", "  File \"/usr/local/lib/python3.10/multiprocessing/process.py\", line 108, in run\n    self._target(*self._args, **self._kwargs)\n", "  File \"/usr/local/lib/python3.10/site-packages/mage_ai/orchestration/queue/process_queue.py\", line 353, in poll_job_and_execute\n    worker.start()\n", "  File \"/usr/local/lib/python3.10/multiprocessing/process.py\", line 121, in start\n    self._popen = self._Popen(self)\n", "  File \"/usr/local/lib/python3.10/multiprocessing/context.py\", line 224, in _Popen\n    return _default_context.get_context().Process._Popen(process_obj)\n", "  File \"/usr/local/lib/python3.10/multiprocessing/context.py\", line 281, in _Popen\n    return Popen(process_obj)\n", "  File \"/usr/local/lib/python3.10/multiprocessing/popen_fork.py\", line 19, in __init__\n    self._launch(process_obj)\n", "  File \"/usr/local/lib/python3.10/multiprocessing/popen_fork.py\", line 71, in _launch\n    code = process_obj._bootstrap(parent_sentinel=child_r)\n", "  File \"/usr/local/lib/python3.10/multiprocessing/process.py\", line 314, in _bootstrap\n    self.run()\n", "  File \"/usr/local/lib/python3.10/site-packages/newrelic/api/background_task.py\", line 117, in wrapper\n    return wrapped(*args, **kwargs)\n", "  File \"/usr/local/lib/python3.10/site-packages/mage_ai/orchestration/queue/process_queue.py\", line 317, in run\n    start_session_and_run(args[1], *args[2], **args[3])\n", "  File \"/usr/local/lib/python3.10/site-packages/mage_ai/orchestration/db/process.py\", line 15, in start_session_and_run\n    results = target(*args)\n", "  File \"/usr/local/lib/python3.10/site-packages/mage_ai/orchestration/pipeline_scheduler_original.py\", line 1311, in run_block\n    return ExecutorFactory.get_block_executor(\n", "  File \"/usr/local/lib/python3.10/site-packages/mage_ai/data_preparation/executors/block_executor.py\", line 682, in execute\n    on_failure(\n", "  File \"/usr/local/lib/python3.10/site-packages/mage_ai/orchestration/db/__init__.py\", line 159, in func_with_rollback\n    return func(*args, **kwargs)\n", "  File \"/usr/local/lib/python3.10/site-packages/mage_ai/orchestration/pipeline_scheduler_original.py\", line 465, in on_block_failure\n    self.logger.exception(\n", "  File \"/usr/local/lib/python3.10/site-packages/mage_ai/data_preparation/logging/logger.py\", line 30, in exception\n    self.__send_message('exception', message, **kwargs)\n", "  File \"/usr/local/lib/python3.10/site-packages/mage_ai/data_preparation/logging/logger.py\", line 65, in __send_message\n    data['error_stack'] = traceback.format_stack()\n"], "error_stacktrace": "duplicate key value violates unique constraint \"qb_customers_pkey\"\nDETAIL:  Key (id)=(1) already exists.\nCONTEXT:  COPY qb_customers, line 1\n"}
Traceback (most recent call last):
  File "/usr/local/lib/python3.10/site-packages/mage_ai/data_preparation/executors/block_executor.py", line 647, in execute
    result = __execute_with_retry()
  File "/usr/local/lib/python3.10/site-packages/mage_ai/shared/retry.py", line 54, in retry_func
    raise e
  File "/usr/local/lib/python3.10/site-packages/mage_ai/shared/retry.py", line 38, in retry_func
    return func(*args, **kwargs)
  File "/usr/local/lib/python3.10/site-packages/mage_ai/data_preparation/executors/block_executor.py", line 621, in __execute_with_retry
    return self._execute(
  File "/usr/local/lib/python3.10/site-packages/mage_ai/data_preparation/executors/block_executor.py", line 1154, in _execute
    result = self.block.execute_sync(
  File "/usr/local/lib/python3.10/site-packages/mage_ai/data_preparation/models/block/__init__.py", line 1691, in execute_sync
    return __execute()
  File "/usr/local/lib/python3.10/site-packages/mage_ai/data_preparation/models/block/__init__.py", line 1668, in __execute
    raise err
  File "/usr/local/lib/python3.10/site-packages/mage_ai/data_preparation/models/block/__init__.py", line 1570, in __execute
    output = self.execute_block(
  File "/usr/local/lib/python3.10/site-packages/mage_ai/data_preparation/models/block/__init__.py", line 1910, in execute_block
    outputs = self._execute_block(
  File "/usr/local/lib/python3.10/site-packages/mage_ai/data_preparation/models/block/__init__.py", line 2073, in _execute_block
    outputs = self.execute_block_function(
  File "/usr/local/lib/python3.10/site-packages/mage_ai/data_preparation/models/block/__init__.py", line 2169, in execute_block_function
    output = block_function_updated(*input_vars, **global_vars)
  File "<string>", line 61, in save_to_raw_customers
  File "/usr/local/lib/python3.10/site-packages/mage_ai/io/sql.py", line 380, in export
    __process()
  File "/usr/local/lib/python3.10/site-packages/mage_ai/io/sql.py", line 360, in __process
    self.upload_dataframe(
  File "/usr/local/lib/python3.10/site-packages/mage_ai/io/postgres.py", line 415, in upload_dataframe
    cursor.copy_expert(f"""
psycopg2.errors.UniqueViolation: duplicate key value violates unique constraint "qb_customers_pkey"
DETAIL:  Key (id)=(1) already exists.
CONTEXT:  COPY qb_customers, line 1

2025-09-13T03:23:11 {"cpu": 0.6689453125, "cpu_total": 8, "cpu_usage": 0.0836181640625, "memory": 7222.0, "memory_total": 15719.0, "memory_usage": 0.4594439849863223, "pipeline_run_id": 4, "pipeline_schedule_id": 1, "pipeline_uuid": "qb_invoices_backfill", "hostname": "3dcda474a3e7", "level": "INFO", "message": "Pipeline qb_invoices_backfill for run 4 in schedule 1 is alive.", "timestamp": 1757733791.089514, "uuid": "6ee826f1cbd245aa904ac1d307cf8d0b"}
2025-09-13T03:23:52 {"cpu": 0.70458984375, "cpu_total": 8, "cpu_usage": 0.08807373046875, "memory": 7265.0, "memory_total": 15719.0, "memory_usage": 0.4621795279597939, "pipeline_run_id": 6, "pipeline_schedule_id": 1, "pipeline_uuid": "qb_invoices_backfill", "hostname": "3dcda474a3e7", "level": "INFO", "message": "Pipeline qb_invoices_backfill for run 6 in schedule 1 is alive.", "timestamp": 1757733832.102663, "uuid": "bb8fadcdecda4e91b2d971529167b7e5"}
2025-09-13T03:23:52 {"block_run_id": 9, "block_uuid": "extract_qb_invoices", "pipeline_run_id": 6, "pipeline_schedule_id": 1, "pipeline_uuid": "qb_invoices_backfill", "hostname": "3dcda474a3e7", "level": "INFO", "message": "Execute PipelineRun 6, BlockRun 9: pipeline qb_invoices_backfill block extract_qb_invoices", "timestamp": 1757733832.158716, "uuid": "0043680bde2a47d7b6e95d2b6f1efb21"}
2025-09-13T03:23:52 {"cpu": 0.70458984375, "cpu_total": 8, "cpu_usage": 0.08807373046875, "memory": 7317.0, "memory_total": 15719.0, "memory_usage": 0.46548762643934094, "pipeline_run_id": 6, "pipeline_schedule_id": 1, "pipeline_uuid": "qb_invoices_backfill", "hostname": "3dcda474a3e7", "level": "INFO", "message": "Pipeline qb_invoices_backfill for run 6 in schedule 1 is alive.", "timestamp": 1757733832.179424, "uuid": "6be67afe84374767b223e370d0415ba7"}
2025-09-13T03:23:54 {"block_run_id": 9, "block_uuid": "extract_qb_invoices", "pipeline_run_id": 6, "pipeline_schedule_id": 1, "pipeline_uuid": "qb_invoices_backfill", "hostname": "3dcda474a3e7", "level": "INFO", "message": "BlockRun 9 (block_uuid: extract_qb_invoices) completes.", "timestamp": 1757733834.497588, "uuid": "3fd8607d88d94cb38a084e059a66a051"}
2025-09-13T03:24:02 {"cpu": 0.69677734375, "cpu_total": 8, "cpu_usage": 0.08709716796875, "memory": 7473.0, "memory_total": 15719.0, "memory_usage": 0.47541192187798204, "pipeline_run_id": 6, "pipeline_schedule_id": 1, "pipeline_uuid": "qb_invoices_backfill", "hostname": "3dcda474a3e7", "level": "INFO", "message": "Pipeline qb_invoices_backfill for run 6 in schedule 1 is alive.", "timestamp": 1757733842.253117, "uuid": "f3f5627ab6774a42b71fb3d077f89908"}
2025-09-13T03:24:03 {"block_run_id": 10, "block_uuid": "save_to_raw_invoices", "pipeline_run_id": 6, "pipeline_schedule_id": 1, "pipeline_uuid": "qb_invoices_backfill", "hostname": "3dcda474a3e7", "level": "INFO", "message": "Execute PipelineRun 6, BlockRun 10: pipeline qb_invoices_backfill block save_to_raw_invoices", "timestamp": 1757733843.296901, "uuid": "d2bbdb378c814f50a3bad7279b62e0c8"}
2025-09-13T03:24:04 {"block_run_id": 10, "block_uuid": "save_to_raw_invoices", "pipeline_run_id": 6, "pipeline_schedule_id": 1, "pipeline_uuid": "qb_invoices_backfill", "hostname": "3dcda474a3e7", "level": "EXCEPTION", "message": "BlockRun 10 (block_uuid: save_to_raw_invoices) failed.", "timestamp": 1757733844.055842, "uuid": "6600aadffa9d400699389a11a12be6cb", "error": "Traceback (most recent call last):\n  File \"/usr/local/lib/python3.10/site-packages/mage_ai/data_preparation/executors/block_executor.py\", line 647, in execute\n    result = __execute_with_retry()\n  File \"/usr/local/lib/python3.10/site-packages/mage_ai/shared/retry.py\", line 54, in retry_func\n    raise e\n  File \"/usr/local/lib/python3.10/site-packages/mage_ai/shared/retry.py\", line 38, in retry_func\n    return func(*args, **kwargs)\n  File \"/usr/local/lib/python3.10/site-packages/mage_ai/data_preparation/executors/block_executor.py\", line 621, in __execute_with_retry\n    return self._execute(\n  File \"/usr/local/lib/python3.10/site-packages/mage_ai/data_preparation/executors/block_executor.py\", line 1154, in _execute\n    result = self.block.execute_sync(\n  File \"/usr/local/lib/python3.10/site-packages/mage_ai/data_preparation/models/block/__init__.py\", line 1691, in execute_sync\n    return __execute()\n  File \"/usr/local/lib/python3.10/site-packages/mage_ai/data_preparation/models/block/__init__.py\", line 1668, in __execute\n    raise err\n  File \"/usr/local/lib/python3.10/site-packages/mage_ai/data_preparation/models/block/__init__.py\", line 1570, in __execute\n    output = self.execute_block(\n  File \"/usr/local/lib/python3.10/site-packages/mage_ai/data_preparation/models/block/__init__.py\", line 1910, in execute_block\n    outputs = self._execute_block(\n  File \"/usr/local/lib/python3.10/site-packages/mage_ai/data_preparation/models/block/__init__.py\", line 2073, in _execute_block\n    outputs = self.execute_block_function(\n  File \"/usr/local/lib/python3.10/site-packages/mage_ai/data_preparation/models/block/__init__.py\", line 2169, in execute_block_function\n    output = block_function_updated(*input_vars, **global_vars)\n  File \"<string>\", line 61, in save_to_raw_customers\n  File \"/usr/local/lib/python3.10/site-packages/mage_ai/io/sql.py\", line 380, in export\n    __process()\n  File \"/usr/local/lib/python3.10/site-packages/mage_ai/io/sql.py\", line 360, in __process\n    self.upload_dataframe(\n  File \"/usr/local/lib/python3.10/site-packages/mage_ai/io/postgres.py\", line 415, in upload_dataframe\n    cursor.copy_expert(f\"\"\"\npsycopg2.errors.UniqueViolation: duplicate key value violates unique constraint \"qb_customers_pkey\"\nDETAIL:  Key (id)=(1) already exists.\nCONTEXT:  COPY qb_customers, line 1\n\n", "error_stack": ["  File \"/usr/local/bin/mage\", line 8, in <module>\n    sys.exit(app())\n", "  File \"/usr/local/lib/python3.10/site-packages/typer/main.py\", line 311, in __call__\n    return get_command(self)(*args, **kwargs)\n", "  File \"/usr/local/lib/python3.10/site-packages/click/core.py\", line 1442, in __call__\n    return self.main(*args, **kwargs)\n", "  File \"/usr/local/lib/python3.10/site-packages/typer/core.py\", line 778, in main\n    return _main(\n", "  File \"/usr/local/lib/python3.10/site-packages/typer/core.py\", line 216, in _main\n    rv = self.invoke(ctx)\n", "  File \"/usr/local/lib/python3.10/site-packages/click/core.py\", line 1830, in invoke\n    return _process_result(sub_ctx.command.invoke(sub_ctx))\n", "  File \"/usr/local/lib/python3.10/site-packages/click/core.py\", line 1226, in invoke\n    return ctx.invoke(self.callback, **ctx.params)\n", "  File \"/usr/local/lib/python3.10/site-packages/click/core.py\", line 794, in invoke\n    return callback(*args, **kwargs)\n", "  File \"/usr/local/lib/python3.10/site-packages/typer/main.py\", line 683, in wrapper\n    return callback(**use_params)  # type: ignore\n", "  File \"/usr/local/lib/python3.10/site-packages/mage_ai/cli/main.py\", line 147, in start\n    start_server(\n", "  File \"/usr/local/lib/python3.10/site-packages/mage_ai/server/server.py\", line 809, in start_server\n    scheduler_manager.start_scheduler()\n", "  File \"/usr/local/lib/python3.10/site-packages/mage_ai/server/scheduler_manager.py\", line 108, in start_scheduler\n    proc.start()\n", "  File \"/usr/local/lib/python3.10/multiprocessing/process.py\", line 121, in start\n    self._popen = self._Popen(self)\n", "  File \"/usr/local/lib/python3.10/multiprocessing/context.py\", line 224, in _Popen\n    return _default_context.get_context().Process._Popen(process_obj)\n", "  File \"/usr/local/lib/python3.10/multiprocessing/context.py\", line 281, in _Popen\n    return Popen(process_obj)\n", "  File \"/usr/local/lib/python3.10/multiprocessing/popen_fork.py\", line 19, in __init__\n    self._launch(process_obj)\n", "  File \"/usr/local/lib/python3.10/multiprocessing/popen_fork.py\", line 71, in _launch\n    code = process_obj._bootstrap(parent_sentinel=child_r)\n", "  File \"/usr/local/lib/python3.10/multiprocessing/process.py\", line 314, in _bootstrap\n    self.run()\n", "  File \"/usr/local/lib/python3.10/multiprocessing/process.py\", line 108, in run\n    self._target(*self._args, **self._kwargs)\n", "  File \"/usr/local/lib/python3.10/site-packages/mage_ai/orchestration/db/process.py\", line 15, in start_session_and_run\n    results = target(*args)\n", "  File \"/usr/local/lib/python3.10/site-packages/mage_ai/server/scheduler_manager.py\", line 60, in run_scheduler\n    LoopTimeTrigger().start()\n", "  File \"/usr/local/lib/python3.10/site-packages/mage_ai/orchestration/triggers/loop_time_trigger.py\", line 14, in start\n    self.run()\n", "  File \"/usr/local/lib/python3.10/site-packages/mage_ai/orchestration/triggers/time_trigger.py\", line 11, in run\n    schedule_all()\n", "  File \"/usr/local/lib/python3.10/site-packages/mage_ai/orchestration/pipeline_scheduler_original.py\", line 1819, in schedule_all\n    PipelineScheduler(r).schedule()\n", "  File \"/usr/local/lib/python3.10/site-packages/mage_ai/orchestration/db/__init__.py\", line 159, in func_with_rollback\n    return func(*args, **kwargs)\n", "  File \"/usr/local/lib/python3.10/site-packages/mage_ai/orchestration/pipeline_scheduler_original.py\", line 334, in schedule\n    self.__schedule_blocks(block_runs)\n", "  File \"/usr/local/lib/python3.10/site-packages/mage_ai/orchestration/pipeline_scheduler_original.py\", line 641, in __schedule_blocks\n    job_manager.add_job(\n", "  File \"/usr/local/lib/python3.10/site-packages/mage_ai/orchestration/job_manager.py\", line 21, in add_job\n    self.queue.enqueue(job_id, target, *args, **kwargs)\n", "  File \"/usr/local/lib/python3.10/site-packages/mage_ai/orchestration/queue/process_queue.py\", line 122, in enqueue\n    self.start_worker_pool()\n", "  File \"/usr/local/lib/python3.10/site-packages/mage_ai/orchestration/queue/process_queue.py\", line 199, in start_worker_pool\n    self.worker_pool_proc.start()\n", "  File \"/usr/local/lib/python3.10/multiprocessing/process.py\", line 121, in start\n    self._popen = self._Popen(self)\n", "  File \"/usr/local/lib/python3.10/multiprocessing/context.py\", line 224, in _Popen\n    return _default_context.get_context().Process._Popen(process_obj)\n", "  File \"/usr/local/lib/python3.10/multiprocessing/context.py\", line 281, in _Popen\n    return Popen(process_obj)\n", "  File \"/usr/local/lib/python3.10/multiprocessing/popen_fork.py\", line 19, in __init__\n    self._launch(process_obj)\n", "  File \"/usr/local/lib/python3.10/multiprocessing/popen_fork.py\", line 71, in _launch\n    code = process_obj._bootstrap(parent_sentinel=child_r)\n", "  File \"/usr/local/lib/python3.10/multiprocessing/process.py\", line 314, in _bootstrap\n    self.run()\n", "  File \"/usr/local/lib/python3.10/multiprocessing/process.py\", line 108, in run\n    self._target(*self._args, **self._kwargs)\n", "  File \"/usr/local/lib/python3.10/site-packages/mage_ai/orchestration/queue/process_queue.py\", line 353, in poll_job_and_execute\n    worker.start()\n", "  File \"/usr/local/lib/python3.10/multiprocessing/process.py\", line 121, in start\n    self._popen = self._Popen(self)\n", "  File \"/usr/local/lib/python3.10/multiprocessing/context.py\", line 224, in _Popen\n    return _default_context.get_context().Process._Popen(process_obj)\n", "  File \"/usr/local/lib/python3.10/multiprocessing/context.py\", line 281, in _Popen\n    return Popen(process_obj)\n", "  File \"/usr/local/lib/python3.10/multiprocessing/popen_fork.py\", line 19, in __init__\n    self._launch(process_obj)\n", "  File \"/usr/local/lib/python3.10/multiprocessing/popen_fork.py\", line 71, in _launch\n    code = process_obj._bootstrap(parent_sentinel=child_r)\n", "  File \"/usr/local/lib/python3.10/multiprocessing/process.py\", line 314, in _bootstrap\n    self.run()\n", "  File \"/usr/local/lib/python3.10/site-packages/newrelic/api/background_task.py\", line 117, in wrapper\n    return wrapped(*args, **kwargs)\n", "  File \"/usr/local/lib/python3.10/site-packages/mage_ai/orchestration/queue/process_queue.py\", line 317, in run\n    start_session_and_run(args[1], *args[2], **args[3])\n", "  File \"/usr/local/lib/python3.10/site-packages/mage_ai/orchestration/db/process.py\", line 15, in start_session_and_run\n    results = target(*args)\n", "  File \"/usr/local/lib/python3.10/site-packages/mage_ai/orchestration/pipeline_scheduler_original.py\", line 1311, in run_block\n    return ExecutorFactory.get_block_executor(\n", "  File \"/usr/local/lib/python3.10/site-packages/mage_ai/data_preparation/executors/block_executor.py\", line 682, in execute\n    on_failure(\n", "  File \"/usr/local/lib/python3.10/site-packages/mage_ai/orchestration/db/__init__.py\", line 159, in func_with_rollback\n    return func(*args, **kwargs)\n", "  File \"/usr/local/lib/python3.10/site-packages/mage_ai/orchestration/pipeline_scheduler_original.py\", line 465, in on_block_failure\n    self.logger.exception(\n", "  File \"/usr/local/lib/python3.10/site-packages/mage_ai/data_preparation/logging/logger.py\", line 30, in exception\n    self.__send_message('exception', message, **kwargs)\n", "  File \"/usr/local/lib/python3.10/site-packages/mage_ai/data_preparation/logging/logger.py\", line 65, in __send_message\n    data['error_stack'] = traceback.format_stack()\n"], "error_stacktrace": "duplicate key value violates unique constraint \"qb_customers_pkey\"\nDETAIL:  Key (id)=(1) already exists.\nCONTEXT:  COPY qb_customers, line 1\n"}
Traceback (most recent call last):
  File "/usr/local/lib/python3.10/site-packages/mage_ai/data_preparation/executors/block_executor.py", line 647, in execute
    result = __execute_with_retry()
  File "/usr/local/lib/python3.10/site-packages/mage_ai/shared/retry.py", line 54, in retry_func
    raise e
  File "/usr/local/lib/python3.10/site-packages/mage_ai/shared/retry.py", line 38, in retry_func
    return func(*args, **kwargs)
  File "/usr/local/lib/python3.10/site-packages/mage_ai/data_preparation/executors/block_executor.py", line 621, in __execute_with_retry
    return self._execute(
  File "/usr/local/lib/python3.10/site-packages/mage_ai/data_preparation/executors/block_executor.py", line 1154, in _execute
    result = self.block.execute_sync(
  File "/usr/local/lib/python3.10/site-packages/mage_ai/data_preparation/models/block/__init__.py", line 1691, in execute_sync
    return __execute()
  File "/usr/local/lib/python3.10/site-packages/mage_ai/data_preparation/models/block/__init__.py", line 1668, in __execute
    raise err
  File "/usr/local/lib/python3.10/site-packages/mage_ai/data_preparation/models/block/__init__.py", line 1570, in __execute
    output = self.execute_block(
  File "/usr/local/lib/python3.10/site-packages/mage_ai/data_preparation/models/block/__init__.py", line 1910, in execute_block
    outputs = self._execute_block(
  File "/usr/local/lib/python3.10/site-packages/mage_ai/data_preparation/models/block/__init__.py", line 2073, in _execute_block
    outputs = self.execute_block_function(
  File "/usr/local/lib/python3.10/site-packages/mage_ai/data_preparation/models/block/__init__.py", line 2169, in execute_block_function
    output = block_function_updated(*input_vars, **global_vars)
  File "<string>", line 61, in save_to_raw_customers
  File "/usr/local/lib/python3.10/site-packages/mage_ai/io/sql.py", line 380, in export
    __process()
  File "/usr/local/lib/python3.10/site-packages/mage_ai/io/sql.py", line 360, in __process
    self.upload_dataframe(
  File "/usr/local/lib/python3.10/site-packages/mage_ai/io/postgres.py", line 415, in upload_dataframe
    cursor.copy_expert(f"""
psycopg2.errors.UniqueViolation: duplicate key value violates unique constraint "qb_customers_pkey"
DETAIL:  Key (id)=(1) already exists.
CONTEXT:  COPY qb_customers, line 1

2025-09-13T03:24:13 {"cpu": 0.7109375, "cpu_total": 8, "cpu_usage": 0.0888671875, "memory": 7496.0, "memory_total": 15719.0, "memory_usage": 0.4768751192823971, "pipeline_run_id": 6, "pipeline_schedule_id": 1, "pipeline_uuid": "qb_invoices_backfill", "hostname": "3dcda474a3e7", "level": "INFO", "message": "Pipeline qb_invoices_backfill for run 6 in schedule 1 is alive.", "timestamp": 1757733853.129473, "uuid": "e31912410e91469a81539724ca17b917"}
